File: Textfiles/0-PE-24.txt
#EXPORTTYPE:                  DATA COMPARE                 DATA COMPARE                 DATA COMPARE
#FILE:                        0-PE-24.ngb-sdg              0-PE-24.ngb-sdg              0-PE-24.ngb-sdg
#FORMAT:                      NETZSCH5                     NETZSCH5                     NETZSCH5
#FTYPE:                       ANSI                         ANSI                         ANSI
#IDENTITY:                    0-PE-24                      0-PE-24                      0-PE-24
#DECIMAL:                     POINT                        POINT                        POINT
#SEPARATOR:                   SEMICOLON                    SEMICOLON                    SEMICOLON
#MTYPE:                       DSC                          DSC                          DSC
#INSTRUMENT:                  NETZSCH DSC 214              NETZSCH DSC 214              NETZSCH DSC 214
#PROJECT:
#DATE/TIME:                   01.03.2023 15:50             01.03.2023 15:50             01.03.2023 15:50
#CORR. FILE:
#TEMPCAL:                     15-02-2023 16:42             15-02-2023 16:42             15-02-2023 16:42
#SENSITIVITY:                 15-02-2023 16:42             15-02-2023 16:42             15-02-2023 16:42
#LABORATORY:                  N310                         N310                         N310
#OPERATOR:                    XG                           XG                           XG
#REMARK:
#SAMPLE:                      0-PE-24                      0-PE-24                      0-PE-24
#SAMPLE MASS /mg:             1.5                          1.5                          1.5
#MATERIAL:
#REFERENCE:                   -----                        -----                        -----
#REFERENCE MASS /mg:          0                            0                            0
#TYPE OF CRUCIBLE:            Concavus Pan Al, pierced lid Concavus Pan Al, pierced lid Concavus Pan Al, pierced lid
#SAMPLE CRUCIBLE MASS /mg:    0                            0                            0
#REFERENCE CRUCIBLE MASS /mg: 0                            0                            0
#PURGE 1 MFC:                 AIR(80/20),250,3 ml/min      AIR(80/20),250,3 ml/min      AIR(80/20),250,3 ml/min
#PURGE 2 MFC:                 ARGON,240,3 ml/min           ARGON,240,3 ml/min           ARGON,240,3 ml/min
#PROTECTIVE MFC:              ARGON,240,3 ml/min           ARGON,240,3 ml/min           ARGON,240,3 ml/min
#M.RANGE /µV:                 5000                         5000                         5000
#TAU-R:                       15-02-2023 16:42             15-02-2023 16:42             15-02-2023 16:42
#CORR. CODE:                  050                          050                          050
#EXO:                         -1                           -1                           -1
#RANGE:                       20°C/20.0(K/min)/300°C       300°C/20.0(K/min)/-50°C      -50°C/20.0(K/min)/300°C
#SEGMENT:                     S1/5                         S3/5                         S5/5
#SEG. 5:                                                                                -50°C/20.0(K/min)/300°C
#SEG. 3:                                                   300°C/20.0(K/min)/-50°C
#SEG. 1:                      20°C/20.0(K/min)/300°C

##Temp./°C;DSC/(mW/mg);DSC/(mW/mg);DSC/(mW/mg)
-49.04956;            ;-1.02640;7.338912e-03
-48.04956;            ;-0.96316;     1.36890
-47.04956;            ;-1.06391;     1.73536
-46.04956;            ;-1.17175;     1.90923
-45.04956;            ;-1.27145;     1.97138
-44.04956;            ;-1.36261;     1.96679
-43.04956;            ;-1.41413;     1.91854
-42.04956;            ;-1.43763;     1.83949
-41.04956;            ;-1.47341;     1.74899
-40.04956;            ;-1.48759;     1.67218
-39.04956;            ;-1.49143;     1.59843
-38.04956;            ;-1.49681;     1.54725
-37.04956;            ;-1.50286;     1.50237
-36.04956;            ;-1.50829;     1.48157
-35.04956;            ;-1.51304;     1.47935
-34.04956;            ;-1.51830;     1.49500
-33.04956;            ;-1.52338;     1.51604
-32.04956;            ;-1.52774;     1.54214
-31.04956;            ;-1.53139;     1.56776
-30.04956;            ;-1.53224;     1.58777
-29.04956;            ;-1.53483;     1.60777
-28.04956;            ;-1.53713;     1.62153
-27.04956;            ;-1.54222;     1.63456
-26.04956;            ;-1.54628;     1.64373
-25.04956;            ;-1.55182;     1.65123
-24.04956;            ;-1.55672;     1.65477
-23.04956;            ;-1.56366;     1.65974
-22.04956;            ;-1.56835;     1.66513
-21.04956;            ;-1.57528;     1.67307
-20.04956;            ;-1.58010;     1.68058
-19.04956;            ;-1.58542;     1.69066
-18.04956;            ;-1.58970;     1.69914
-17.04956;            ;-1.59459;     1.70739
-16.04956;            ;-1.59926;     1.71867
-15.04956;            ;-1.60277;     1.72614
-14.04956;            ;-1.60683;     1.73379
-13.04956;            ;-1.61069;     1.74179
-12.04956;            ;-1.61472;     1.75063
-11.04956;            ;-1.61798;     1.75698
-10.04956;            ;-1.62112;     1.76416
 -9.04956;            ;-1.62442;     1.77071
 -8.04956;            ;-1.62808;     1.77843
 -7.04956;            ;-1.63291;     1.78671
 -6.04956;            ;-1.63611;     1.79383
 -5.04956;            ;-1.64136;     1.80165
 -4.04956;            ;-1.64404;     1.80955
 -3.04956;            ;-1.64921;     1.81854
 -2.04956;            ;-1.65331;     1.82508
 -1.04956;            ;-1.65837;     1.83268
 -0.04956;            ;-1.66304;     1.84033
  0.95044;            ;-1.66724;     1.84935
  1.95044;            ;-1.67054;     1.85609
  2.95044;            ;-1.67311;     1.86355
  3.95044;            ;-1.67594;     1.87229
  4.95044;            ;-1.67932;     1.87847
  5.95044;            ;-1.68363;     1.88489
  6.95044;            ;-1.69060;     1.89204
  7.95044;            ;-1.69850;     1.89863
  8.95044;            ;-1.70496;     1.90788
  9.95044;            ;-1.70936;     1.91604
 10.95044;            ;-1.71226;     1.92091
 11.95044;            ;-1.71630;     1.92733
 12.95044;            ;-1.72198;     1.93379
 13.95044;            ;-1.72772;     1.94025
 14.95044;            ;-1.73250;     1.94461
 15.95044;            ;-1.73712;     1.95014
 16.95044;            ;-1.74234;     1.95502
 17.95044;            ;-1.74716;     1.95932
 18.95044;5.675405e-02;-1.75147;     1.96753
 19.95044;5.675405e-02;-1.75680;     1.97418
 20.95044;     0.91496;-1.76126;     1.97999
 21.95044;     1.83850;-1.76631;     1.98740
 22.95044;     2.17421;-1.77118;     1.99413
 23.95044;     2.32847;-1.77592;     2.00273
 24.95044;     2.38158;-1.78076;     2.00943
 25.95044;     2.36575;-1.78489;     2.01501
 26.95044;     2.30431;-1.79042;     2.02173
 27.95044;     2.21178;-1.79627;     2.02535
 28.95044;     2.11015;-1.80104;     2.03095
 29.95044;     2.01342;-1.80803;     2.03602
 30.95044;     1.92881;-1.81453;     2.04180
 31.95044;     1.84638;-1.82208;     2.04927
 32.95044;     1.80173;-1.82869;     2.05688
 33.95044;     1.77289;-1.83594;     2.06441
 34.95044;     1.78179;-1.84506;     2.07273
 35.95044;     1.81070;-1.85314;     2.07981
 36.95044;     1.85297;-1.86073;     2.08816
 37.95044;     1.89921;-1.86992;     2.09538
 38.95044;     1.94059;-1.88007;     2.10225
 39.95044;     1.97721;-1.89139;     2.10958
 40.95044;     2.00839;-1.90269;     2.11717
 41.95044;     2.02923;-1.91723;     2.12535
 42.95044;     2.04418;-1.92781;     2.13301
 43.95044;     2.05587;-1.94463;     2.14055
 44.95044;     2.06613;-1.96161;     2.14831
 45.95044;     2.07352;-1.97865;     2.15608
 46.95044;     2.08185;-1.99967;     2.16544
 47.95044;     2.09081;-2.01890;     2.17392
 48.95044;     2.10032;-2.04273;     2.18188
 49.95044;     2.11184;-2.06714;     2.18953
 50.95044;     2.12495;-2.09160;     2.19714
 51.95044;     2.13827;-2.11539;     2.20533
 52.95044;     2.15484;-2.13633;     2.21393
 53.95044;     2.17391;-2.15004;     2.22400
 54.95044;     2.19664;-2.15553;     2.23269
 55.95044;     2.22319;-2.15266;     2.24202
 56.95044;     2.25109;-2.14114;     2.25247
 57.95044;     2.27689;-2.12133;     2.26153
 58.95044;     2.29760;-2.09883;     2.27037
 59.95044;     2.31763;-2.08049;     2.28081
 60.95044;     2.33169;-2.07009;     2.29112
 61.95044;     2.34404;-2.06570;     2.30105
 62.95044;     2.35180;-2.06429;     2.31158
 63.95044;     2.35427;-2.06574;     2.32213
 64.95044;     2.35856;-2.06948;     2.33267
 65.95044;     2.36265;-2.07619;     2.34561
 66.95044;     2.36659;-2.08241;     2.35777
 67.95044;     2.37218;-2.09169;     2.37084
 68.95044;     2.37833;-2.10131;     2.38239
 69.95044;     2.38231;-2.11063;     2.39711
 70.95044;     2.38946;-2.12185;     2.41068
 71.95044;     2.39720;-2.13761;     2.42480
 72.95044;     2.40411;-2.15069;     2.43932
 73.95044;     2.41236;-2.16390;     2.45337
 74.95044;     2.42073;-2.18164;     2.46867
 75.95044;     2.42816;-2.19773;     2.48397
 76.95044;     2.43783;-2.21670;     2.49971
 77.95044;     2.44979;-2.23634;     2.51537
 78.95044;     2.46077;-2.26366;     2.53278
 79.95044;     2.47160;-2.27534;     2.54864
 80.95044;     2.48287;-2.30658;     2.56602
 81.95044;     2.49603;-2.32986;     2.58581
 82.95044;     2.50885;-2.36922;     2.60442
 83.95044;     2.52257;-2.39802;     2.62317
 84.95044;     2.53717;-2.44073;     2.64132
 85.95044;     2.55094;-2.49098;     2.66037
 86.95044;     2.56431;-2.55589;     2.68296
 87.95044;     2.58312;-2.67324;     2.70854
 88.95044;     2.59958;-2.90717;     2.73016
 89.95044;     2.61468;-3.36962;     2.75500
 90.95044;     2.63288;-3.86542;     2.78483
 91.95044;     2.65093;-5.35904;     2.81230
 92.95044;     2.67353;-8.13992;     2.84202
 93.95044;     2.70000;-6.55765;     2.87221
 94.95044;     2.72496;-3.42823;     2.90906
 95.95044;     2.75704;-2.27821;     2.94428
 96.95044;     2.79417;-1.93740;     2.98131
 97.95044;     2.84607;-1.82622;     3.02077
 98.95044;     2.89791;-1.79400;     3.06711
 99.95044;     2.95774;-1.79528;     3.12060
100.95044;     3.03522;-1.78788;     3.18053
101.95044;     3.13642;-1.79254;     3.26088
102.95044;     3.26141;-1.79372;     3.37750
103.95044;     3.41944;-1.79426;     3.54166
104.95044;     3.61213;-1.79543;     3.76493
105.95044;     3.83772;-1.79617;     4.06404
106.95044;     4.07222;-1.79774;     4.52374
107.95044;     4.30689;-1.79835;     5.05320
108.95044;     4.60052;-1.79959;     5.14146
109.95044;     4.95464;-1.80068;     4.80961
110.95044;     5.26189;-1.80105;     4.19658
111.95044;     4.94899;-1.80237;     3.12416
112.95044;     3.85731;-1.80321;     2.51583
113.95044;     2.83978;-1.80463;     2.39872
114.95044;     2.51580;-1.80584;     2.34849
115.95044;     2.42942;-1.80720;     2.31942
116.95044;     2.37667;-1.80830;     2.29811
117.95044;     2.34312;-1.81004;     2.28172
118.95044;     2.31790;-1.81094;     2.27023
119.95044;     2.30641;-1.81233;     2.26595
120.95044;     2.29113;-1.81364;     2.26368
121.95044;     2.28847;-1.81558;     2.26458
122.95044;     2.28173;-1.81639;     2.26001
123.95044;     2.28288;-1.81764;     2.26091
124.95044;     2.27827;-1.81862;     2.26754
125.95044;     2.27623;-1.81958;     2.27289
126.95044;     2.27823;-1.82040;     2.27310
127.95044;     2.28290;-1.82099;     2.27706
128.95044;     2.28523;-1.82171;     2.28038
129.95044;     2.28965;-1.82244;     2.28238
130.95044;     2.29234;-1.82412;     2.28490
131.95044;     2.29744;-1.82533;     2.29061
132.95044;     2.30011;-1.82716;     2.29460
133.95044;     2.30364;-1.82815;     2.29907
134.95044;     2.30801;-1.82970;     2.30341
135.95044;     2.31259;-1.83035;     2.30885
136.95044;     2.31608;-1.83151;     2.31270
137.95044;     2.32164;-1.83245;     2.31609
138.95044;     2.32590;-1.83350;     2.32087
139.95044;     2.33021;-1.83423;     2.32480
140.95044;     2.33446;-1.83526;     2.33085
141.95044;     2.33854;-1.83579;     2.33397
142.95044;     2.34277;-1.83709;     2.33758
143.95044;     2.34627;-1.83777;     2.34217
144.95044;     2.35016;-1.83878;     2.34548
145.95044;     2.35538;-1.84123;     2.34909
146.95044;     2.35886;-1.84287;     2.35277
147.95044;     2.36298;-1.84465;     2.35793
148.95044;     2.36692;-1.84679;     2.36348
149.95044;     2.37104;-1.84833;     2.36695
150.95044;     2.37501;-1.85013;     2.37078
151.95044;     2.37794;-1.85180;     2.37486
152.95044;     2.38090;-1.85342;     2.37769
153.95044;     2.38413;-1.85523;     2.38297
154.95044;     2.38914;-1.85674;     2.38851
155.95044;     2.39405;-1.85792;     2.39236
156.95044;     2.39701;-1.85908;     2.39670
157.95044;     2.40011;-1.86040;     2.40218
158.95044;     2.40408;-1.86141;     2.40596
159.95044;     2.40787;-1.86251;     2.41107
160.95044;     2.41221;-1.86349;     2.41653
161.95044;     2.41800;-1.86500;     2.41915
162.95044;     2.42183;-1.86684;     2.42270
163.95044;     2.42448;-1.86814;     2.42659
164.95044;     2.42797;-1.87002;     2.43060
165.95044;     2.43198;-1.87167;     2.43518
166.95044;     2.43569;-1.87377;     2.43993
167.95044;     2.44112;-1.87514;     2.44493
168.95044;     2.44038;-1.87677;     2.44931
169.95044;     2.41680;-1.87833;     2.45255
170.95044;     2.43633;-1.87937;     2.45766
171.95044;     2.44165;-1.88053;     2.46359
172.95044;     2.45121;-1.88120;     2.46481
173.95044;     2.45744;-1.88247;     2.41776
174.95044;     2.46108;-1.88360;     2.43954
175.95044;     2.46436;-1.88475;     2.46829
176.95044;     2.46927;-1.88592;     2.47577
177.95044;     2.47434;-1.88707;     2.47951
178.95044;     2.47797;-1.88846;     2.48219
179.95044;     2.48128;-1.89002;     2.48711
180.95044;     2.48593;-1.89112;     2.49210
181.95044;     2.48964;-1.89267;     2.49600
182.95044;     2.49353;-1.89411;     2.49941
183.95044;     2.49776;-1.89581;     2.50433
184.95044;     2.50279;-1.89703;     2.51087
185.95044;     2.50752;-1.89867;     2.51485
186.95044;     2.51070;-1.89995;     2.51962
187.95044;     2.51521;-1.90138;     2.52524
188.95044;     2.51937;-1.90247;     2.52991
189.95044;     2.52475;-1.90371;     2.53370
190.95044;     2.52996;-1.90466;     2.53804
191.95044;     2.53465;-1.90528;     2.54346
192.95044;     2.54069;-1.90658;     2.54870
193.95044;     2.54394;-1.90699;     2.55214
194.95044;     2.54718;-1.90814;     2.55728
195.95044;     2.55242;-1.90904;     2.56264
196.95044;     2.55668;-1.91024;     2.56765
197.95044;     2.56107;-1.91120;     2.57264
198.95044;     2.56589;-1.91197;     2.57693
199.95044;     2.57025;-1.91325;     2.58083
200.95044;     2.57403;-1.91384;     2.58481
201.95044;     2.57943;-1.91517;     2.58855
202.95044;     2.58415;-1.91587;     2.59325
203.95044;     2.58871;-1.91761;     2.59868
204.95044;     2.59424;-1.91864;     2.60337
205.95044;     2.59928;-1.92049;     2.60967
206.95044;     2.60400;-1.92108;     2.61700
207.95044;     2.60852;-1.92247;     2.62335
208.95044;     2.61272;-1.92390;     2.62855
209.95044;     2.61590;-1.92502;     2.63344
210.95044;     2.62055;-1.92627;     2.63866
211.95044;     2.62592;-1.92700;     2.64312
212.95044;     2.63045;-1.92782;     2.64726
213.95044;     2.63398;-1.92806;     2.65008
214.95044;     2.63872;-1.92869;     2.65283
215.95044;     2.64331;-1.93002;     2.65692
216.95044;     2.64833;-1.93205;     2.66295
217.95044;     2.65359;-1.93502;     2.66824
218.95044;     2.65812;-1.93675;     2.67241
219.95044;     2.66409;-1.93803;     2.67936
220.95044;     2.66926;-1.93717;     2.68729
221.95044;     2.67404;-1.93856;     2.69088
222.95044;     2.67775;-1.93949;     2.69369
223.95044;     2.68130;-1.94064;     2.69883
224.95044;     2.68519;-1.94164;     2.70454
225.95044;     2.69118;-1.94321;     2.71074
226.95044;     2.69530;-1.94433;     2.71508
227.95044;     2.69871;-1.94567;     2.71991
228.95044;     2.70355;-1.94701;     2.72597
229.95044;     2.70656;-1.94730;     2.73123
230.95044;     2.70965;-1.94787;     2.73566
231.95044;     2.71445;-1.94851;     2.74033
232.95044;     2.72051;-1.94872;     2.74478
233.95044;     2.72632;-1.94992;     2.74998
234.95044;     2.73023;-1.95072;     2.75552
235.95044;     2.73414;-1.95159;     2.76196
236.95044;     2.73975;-1.95282;     2.76836
237.95044;     2.74409;-1.95341;     2.77468
238.95044;     2.74912;-1.95396;     2.78281
239.95044;     2.75539;-1.95436;     2.78984
240.95044;     2.76204;-1.95494;     2.79757
241.95044;     2.76796;-1.95583;     2.80482
242.95044;     2.77344;-1.95641;     2.81265
243.95044;     2.77868;-1.95707;     2.81979
244.95044;     2.78256;-1.95757;     2.82373
245.95044;     2.78983;-1.95823;     2.82932
246.95044;     2.79788;-1.95918;     2.83632
247.95044;     2.80400;-1.95954;     2.84366
248.95044;     2.81392;-1.95994;     2.84892
249.95044;     2.82241;-1.96018;     2.85613
250.95044;     2.82817;-1.96029;     2.86692
251.95044;     2.83442;-1.96014;     2.87493
252.95044;     2.84207;-1.96038;     2.88341
253.95044;     2.84757;-1.96069;     2.89117
254.95044;     2.85600;-1.96094;     2.89934
255.95044;     2.86438;-1.96121;     2.90732
256.95044;     2.87312;-1.96180;     2.91532
257.95044;     2.88165;-1.96277;     2.92148
258.95044;     2.89070;-1.96386;     2.93038
259.95044;     2.89956;-1.96442;     2.93789
260.95044;     2.90843;-1.96426;     2.94619
261.95044;     2.91696;-1.96437;     2.95562
262.95044;     2.92694;-1.96403;     2.96501
263.95044;     2.93661;-1.96346;     2.97422
264.95044;     2.94693;-1.96275;     2.98345
265.95044;     2.95794;-1.96179;     2.99152
266.95044;     2.96579;-1.96183;     2.99967
267.95044;     2.97329;-1.96246;     3.00756
268.95044;     2.98108;-1.96285;     3.01515
269.95044;     2.98852;-1.97482;     3.02424
270.95044;     2.99706;-1.97444;     3.03422
271.95044;     3.00575;-1.97900;     3.04317
272.95044;     3.01364;-1.97386;     3.05282
273.95044;     3.02303;-1.98257;     3.06245
274.95044;     3.03304;-1.98861;     3.07251
275.95044;     3.04243;-1.99647;     3.08049
276.95044;     3.05251;-1.99165;     3.08848
277.95044;     3.06149;-2.00050;     3.09675
278.95044;     3.07173;-1.99496;     3.10385
279.95044;     3.08051;-1.97863;     3.11163
280.95044;     3.08996;-1.95948;     3.12107
281.95044;     3.09901;-1.93026;     3.12940
282.95044;     3.10819;-1.89242;     3.13916
283.95044;     3.11716;-1.86447;     3.14784
284.95044;     3.12501;-1.84244;     3.15542
285.95044;     3.13398;-1.85298;     3.16480
286.95044;     3.14281;-1.89034;     3.17407
287.95044;     3.15140;-1.98660;     3.18400
288.95044;     3.16082;-2.12125;     3.19482
289.95044;     3.16979;-2.28505;     3.20133
290.95044;     3.17825;-2.44685;     3.20823
291.95044;     3.18599;-2.59180;     3.21652
292.95044;     3.19457;-2.66492;     3.22524
293.95044;     3.20411;-2.66464;     3.23208
294.95044;     3.21534;-2.56664;     3.23968
295.95044;     3.22660;-2.36431;     3.24988
296.95044;     3.23630;-2.02739;     3.25841
297.95044;     3.24617;-1.42543;     3.26861
298.95044;     3.25382;-0.48016;     3.26742